Workbook
Name OdaListesi: Ayarlar!$A$4:$A$33
Name KaynakListesi: OFFSET(Ayarlar!$C$4,0,0,COUNTA(Ayarlar!$C$4:$C$33),1)
Name TurListesi: OFFSET(Ayarlar!$E$4,0,0,COUNTA(Ayarlar!$E$4:$E$13),1)
Name KaynakAralik: Ayarlar!$C$4:$C$33
Name TurAralik: Ayarlar!$E$4:$E$13
Name MaxKisi: Ayarlar!$H$4
Name RaporTarihi: Rapor!$A$4
Name hGB: Hesap!$B$2:$B$31
Name hGel: Hesap!$C$2:$C$31
Name hGlc: Hesap!$D$2:$D$31
Name hGid: Hesap!$E$2:$E$31
Name hGS: Hesap!$F$2:$F$31
Name hBos: Hesap!$G$2:$G$31
Name hSira: Hesap!$N$2:$N$31
Name hOda: Hesap!$A$2:$A$31
Name kOda: Konaklama!$A$6:$A$1005
Name kAd: Konaklama!$B$6:$B$1005
Name kKisi: Konaklama!$C$6:$C$1005
Name kGiris: Konaklama!$D$6:$D$1005
Name kCikis: Konaklama!$E$6:$E$1005
Name kDurum: Konaklama!$F$6:$F$1005
Name kTutar: Konaklama!$G$6:$G$1005
Name kKaynak: Konaklama!$H$6:$H$1005
Name kSure: Konaklama!$I$6:$I$1005
Name kGunluk: Konaklama!$J$6:$J$1005
Name kKontrol: Konaklama!$K$6:$K$1005
Name kAnahtar: Konaklama!$L$6:$L$1005
Name pTarih: 'Ödemeler'!$A$6:$A$505
Name pOda: 'Ödemeler'!$B$6:$B$505
Name pYapan: 'Ödemeler'!$C$6:$C$505
Name pTutar: 'Ödemeler'!$D$6:$D$505
Name pTur: 'Ödemeler'!$E$6:$E$505
Name pAcik: 'Ödemeler'!$F$6:$F$505
Name pKontrol: 'Ödemeler'!$G$6:$G$505
Name pSira: 'Ödemeler'!$H$6:$H$505

Sheet Rapor
A1: APART GÜN SONU RAPORU
A2: =IF(COUNTIF(kKontrol,"HATA*")+COUNTIF(pKontrol,"HATA*")>0,"⚠ DİKKAT: "&(COUNTIF(kKontrol,"HATA*")+COUNTIF(pKontrol,"HATA*"))&" kayıtta HATA var — Konaklama/Ödemeler sayfalarındaki kırmızı satırları düzeltin",IF(OR(F5<>SUM(hGS),F7<>SUMIFS(kKisi,kGiris,"<="&RaporTarihi,kCikis,">"&RaporTarihi,kDurum,"<>İptal")),"⚠ DİKKAT: gün sonu oda/kişi sayısı tutmuyor — kayıtları kontrol edin",IF(COUNT(pSira)>20,"⚠ DİKKAT: 20'den fazla ödeme var, rapora sığmıyor",IF(I6="","⚠ Kirli boş oda sayısını giriniz (yoksa 0 yazın)","✔ Kontroller temiz — rapor hazır"))))
A4: 46295 | B4: Gün Başı | C4: Gelen | D4: Gelecek | E4: Giden | F4: Gün Sonu | G4: Boş Odalar | H4: BOŞ ODA DURUMU
B5: =SUM(hGB) | C5: =SUM(hGel) | D5: =SUM(hGlc) | E5: =SUM(hGid) | F5: =B5-E5+C5+D5 | G5: =COUNT(OdaListesi)-F5 | H5: =IF(I6="","",(G5-I6)&" ODA BOŞ VE TEMİZ // "&I6&" ODA BOŞ VE KİRLİ")
A6: Oda No | B6: =_xlfn.TEXTJOIN("-",TRUE,Hesap!H2:H31) | C6: =_xlfn.TEXTJOIN("-",TRUE,Hesap!I2:I31) | D6: =_xlfn.TEXTJOIN("-",TRUE,Hesap!J2:J31) | E6: =_xlfn.TEXTJOIN("-",TRUE,Hesap!K2:K31) | F6: =_xlfn.TEXTJOIN("-",TRUE,Hesap!L2:L31) | G6: =_xlfn.TEXTJOIN("-",TRUE,Hesap!M2:M31) | H6: Kirli boş oda sayısı ► | I6: 1
A7: Kişi Sayısı | B7: =SUMIFS(kKisi,kGiris,"<"&RaporTarihi,kCikis,">="&RaporTarihi,kDurum,"Geldi") | C7: =SUMIFS(kKisi,kGiris,RaporTarihi,kDurum,"Geldi") | D7: =SUMIFS(kKisi,kGiris,RaporTarihi,kDurum,"Bekleniyor") | E7: =SUMIFS(kKisi,kCikis,RaporTarihi,kDurum,"Geldi") | F7: =B7-E7+C7+D7 | H7: =G5&" ODA BOŞ"
A9: Oda - Gün Sonu | B9: İsim - Gün Sonu | C9: Kişi Sayısı | D9: Giriş Tarihi | E9: Çıkış Tarihi | F9: Süre (Gün) | G9: Günlük Oda Fiyatı | H9: Toplam Tutar | I9: Açıklama
A10: =IFERROR(INDEX(hOda,MATCH(1,hSira,0)),"") | B10: =IF($K10="","",INDEX(kAd,$K10)) | C10: =IF($K10="","",INDEX(kKisi,$K10)) | D10: =IF($K10="","",INDEX(kGiris,$K10)) | E10: =IF($K10="","",INDEX(kCikis,$K10)) | F10: =IF($K10="","",INDEX(kSure,$K10)) | G10: =IF($K10="","",INDEX(kGunluk,$K10)) | H10: =IF($K10="","",INDEX(kTutar,$K10)) | I10: =IF($K10="","",INDEX(kKaynak,$K10)&IF(INDEX(kDurum,$K10)="Bekleniyor"," (GELECEK)","")) | K10: =IF(A10="","",MATCH(A10,kAnahtar,0))
A11: =IFERROR(INDEX(hOda,MATCH(2,hSira,0)),"") | B11: =IF($K11="","",INDEX(kAd,$K11)) | C11: =IF($K11="","",INDEX(kKisi,$K11)) | D11: =IF($K11="","",INDEX(kGiris,$K11)) | E11: =IF($K11="","",INDEX(kCikis,$K11)) | F11: =IF($K11="","",INDEX(kSure,$K11)) | G11: =IF($K11="","",INDEX(kGunluk,$K11)) | H11: =IF($K11="","",INDEX(kTutar,$K11)) | I11: =IF($K11="","",INDEX(kKaynak,$K11)&IF(INDEX(kDurum,$K11)="Bekleniyor"," (GELECEK)","")) | K11: =IF(A11="","",MATCH(A11,kAnahtar,0))
A12: =IFERROR(INDEX(hOda,MATCH(3,hSira,0)),"") | B12: =IF($K12="","",INDEX(kAd,$K12)) | C12: =IF($K12="","",INDEX(kKisi,$K12)) | D12: =IF($K12="","",INDEX(kGiris,$K12)) | E12: =IF($K12="","",INDEX(kCikis,$K12)) | F12: =IF($K12="","",INDEX(kSure,$K12)) | G12: =IF($K12="","",INDEX(kGunluk,$K12)) | H12: =IF($K12="","",INDEX(kTutar,$K12)) | I12: =IF($K12="","",INDEX(kKaynak,$K12)&IF(INDEX(kDurum,$K12)="Bekleniyor"," (GELECEK)","")) | K12: =IF(A12="","",MATCH(A12,kAnahtar,0))
A13: =IFERROR(INDEX(hOda,MATCH(4,hSira,0)),"") | B13: =IF($K13="","",INDEX(kAd,$K13)) | C13: =IF($K13="","",INDEX(kKisi,$K13)) | D13: =IF($K13="","",INDEX(kGiris,$K13)) | E13: =IF($K13="","",INDEX(kCikis,$K13)) | F13: =IF($K13="","",INDEX(kSure,$K13)) | G13: =IF($K13="","",INDEX(kGunluk,$K13)) | H13: =IF($K13="","",INDEX(kTutar,$K13)) | I13: =IF($K13="","",INDEX(kKaynak,$K13)&IF(INDEX(kDurum,$K13)="Bekleniyor"," (GELECEK)","")) | K13: =IF(A13="","",MATCH(A13,kAnahtar,0))
A14: =IFERROR(INDEX(hOda,MATCH(5,hSira,0)),"") | B14: =IF($K14="","",INDEX(kAd,$K14)) | C14: =IF($K14="","",INDEX(kKisi,$K14)) | D14: =IF($K14="","",INDEX(kGiris,$K14)) | E14: =IF($K14="","",INDEX(kCikis,$K14)) | F14: =IF($K14="","",INDEX(kSure,$K14)) | G14: =IF($K14="","",INDEX(kGunluk,$K14)) | H14: =IF($K14="","",INDEX(kTutar,$K14)) | I14: =IF($K14="","",INDEX(kKaynak,$K14)&IF(INDEX(kDurum,$K14)="Bekleniyor"," (GELECEK)","")) | K14: =IF(A14="","",MATCH(A14,kAnahtar,0))
A15: =IFERROR(INDEX(hOda,MATCH(6,hSira,0)),"") | B15: =IF($K15="","",INDEX(kAd,$K15)) | C15: =IF($K15="","",INDEX(kKisi,$K15)) | D15: =IF($K15="","",INDEX(kGiris,$K15)) | E15: =IF($K15="","",INDEX(kCikis,$K15)) | F15: =IF($K15="","",INDEX(kSure,$K15)) | G15: =IF($K15="","",INDEX(kGunluk,$K15)) | H15: =IF($K15="","",INDEX(kTutar,$K15)) | I15: =IF($K15="","",INDEX(kKaynak,$K15)&IF(INDEX(kDurum,$K15)="Bekleniyor"," (GELECEK)","")) | K15: =IF(A15="","",MATCH(A15,kAnahtar,0))
A16: =IFERROR(INDEX(hOda,MATCH(7,hSira,0)),"") | B16: =IF($K16="","",INDEX(kAd,$K16)) | C16: =IF($K16="","",INDEX(kKisi,$K16)) | D16: =IF($K16="","",INDEX(kGiris,$K16)) | E16: =IF($K16="","",INDEX(kCikis,$K16)) | F16: =IF($K16="","",INDEX(kSure,$K16)) | G16: =IF($K16="","",INDEX(kGunluk,$K16)) | H16: =IF($K16="","",INDEX(kTutar,$K16)) | I16: =IF($K16="","",INDEX(kKaynak,$K16)&IF(INDEX(kDurum,$K16)="Bekleniyor"," (GELECEK)","")) | K16: =IF(A16="","",MATCH(A16,kAnahtar,0))
A17: =IFERROR(INDEX(hOda,MATCH(8,hSira,0)),"") | B17: =IF($K17="","",INDEX(kAd,$K17)) | C17: =IF($K17="","",INDEX(kKisi,$K17)) | D17: =IF($K17="","",INDEX(kGiris,$K17)) | E17: =IF($K17="","",INDEX(kCikis,$K17)) | F17: =IF($K17="","",INDEX(kSure,$K17)) | G17: =IF($K17="","",INDEX(kGunluk,$K17)) | H17: =IF($K17="","",INDEX(kTutar,$K17)) | I17: =IF($K17="","",INDEX(kKaynak,$K17)&IF(INDEX(kDurum,$K17)="Bekleniyor"," (GELECEK)","")) | K17: =IF(A17="","",MATCH(A17,kAnahtar,0))
A18: =IFERROR(INDEX(hOda,MATCH(9,hSira,0)),"") | B18: =IF($K18="","",INDEX(kAd,$K18)) | C18: =IF($K18="","",INDEX(kKisi,$K18)) | D18: =IF($K18="","",INDEX(kGiris,$K18)) | E18: =IF($K18="","",INDEX(kCikis,$K18)) | F18: =IF($K18="","",INDEX(kSure,$K18)) | G18: =IF($K18="","",INDEX(kGunluk,$K18)) | H18: =IF($K18="","",INDEX(kTutar,$K18)) | I18: =IF($K18="","",INDEX(kKaynak,$K18)&IF(INDEX(kDurum,$K18)="Bekleniyor"," (GELECEK)","")) | K18: =IF(A18="","",MATCH(A18,kAnahtar,0))
A19: =IFERROR(INDEX(hOda,MATCH(10,hSira,0)),"") | B19: =IF($K19="","",INDEX(kAd,$K19)) | C19: =IF($K19="","",INDEX(kKisi,$K19)) | D19: =IF($K19="","",INDEX(kGiris,$K19)) | E19: =IF($K19="","",INDEX(kCikis,$K19)) | F19: =IF($K19="","",INDEX(kSure,$K19)) | G19: =IF($K19="","",INDEX(kGunluk,$K19)) | H19: =IF($K19="","",INDEX(kTutar,$K19)) | I19: =IF($K19="","",INDEX(kKaynak,$K19)&IF(INDEX(kDurum,$K19)="Bekleniyor"," (GELECEK)","")) | K19: =IF(A19="","",MATCH(A19,kAnahtar,0))
A20: =IFERROR(INDEX(hOda,MATCH(11,hSira,0)),"") | B20: =IF($K20="","",INDEX(kAd,$K20)) | C20: =IF($K20="","",INDEX(kKisi,$K20)) | D20: =IF($K20="","",INDEX(kGiris,$K20)) | E20: =IF($K20="","",INDEX(kCikis,$K20)) | F20: =IF($K20="","",INDEX(kSure,$K20)) | G20: =IF($K20="","",INDEX(kGunluk,$K20)) | H20: =IF($K20="","",INDEX(kTutar,$K20)) | I20: =IF($K20="","",INDEX(kKaynak,$K20)&IF(INDEX(kDurum,$K20)="Bekleniyor"," (GELECEK)","")) | K20: =IF(A20="","",MATCH(A20,kAnahtar,0))
A21: =IFERROR(INDEX(hOda,MATCH(12,hSira,0)),"") | B21: =IF($K21="","",INDEX(kAd,$K21)) | C21: =IF($K21="","",INDEX(kKisi,$K21)) | D21: =IF($K21="","",INDEX(kGiris,$K21)) | E21: =IF($K21="","",INDEX(kCikis,$K21)) | F21: =IF($K21="","",INDEX(kSure,$K21)) | G21: =IF($K21="","",INDEX(kGunluk,$K21)) | H21: =IF($K21="","",INDEX(kTutar,$K21)) | I21: =IF($K21="","",INDEX(kKaynak,$K21)&IF(INDEX(kDurum,$K21)="Bekleniyor"," (GELECEK)","")) | K21: =IF(A21="","",MATCH(A21,kAnahtar,0))
A22: =IFERROR(INDEX(hOda,MATCH(13,hSira,0)),"") | B22: =IF($K22="","",INDEX(kAd,$K22)) | C22: =IF($K22="","",INDEX(kKisi,$K22)) | D22: =IF($K22="","",INDEX(kGiris,$K22)) | E22: =IF($K22="","",INDEX(kCikis,$K22)) | F22: =IF($K22="","",INDEX(kSure,$K22)) | G22: =IF($K22="","",INDEX(kGunluk,$K22)) | H22: =IF($K22="","",INDEX(kTutar,$K22)) | I22: =IF($K22="","",INDEX(kKaynak,$K22)&IF(INDEX(kDurum,$K22)="Bekleniyor"," (GELECEK)","")) | K22: =IF(A22="","",MATCH(A22,kAnahtar,0))
A23: =IFERROR(INDEX(hOda,MATCH(14,hSira,0)),"") | B23: =IF($K23="","",INDEX(kAd,$K23)) | C23: =IF($K23="","",INDEX(kKisi,$K23)) | D23: =IF($K23="","",INDEX(kGiris,$K23)) | E23: =IF($K23="","",INDEX(kCikis,$K23)) | F23: =IF($K23="","",INDEX(kSure,$K23)) | G23: =IF($K23="","",INDEX(kGunluk,$K23)) | H23: =IF($K23="","",INDEX(kTutar,$K23)) | I23: =IF($K23="","",INDEX(kKaynak,$K23)&IF(INDEX(kDurum,$K23)="Bekleniyor"," (GELECEK)","")) | K23: =IF(A23="","",MATCH(A23,kAnahtar,0))
A24: =IFERROR(INDEX(hOda,MATCH(15,hSira,0)),"") | B24: =IF($K24="","",INDEX(kAd,$K24)) | C24: =IF($K24="","",INDEX(kKisi,$K24)) | D24: =IF($K24="","",INDEX(kGiris,$K24)) | E24: =IF($K24="","",INDEX(kCikis,$K24)) | F24: =IF($K24="","",INDEX(kSure,$K24)) | G24: =IF($K24="","",INDEX(kGunluk,$K24)) | H24: =IF($K24="","",INDEX(kTutar,$K24)) | I24: =IF($K24="","",INDEX(kKaynak,$K24)&IF(INDEX(kDurum,$K24)="Bekleniyor"," (GELECEK)","")) | K24: =IF(A24="","",MATCH(A24,kAnahtar,0))
A25: =IFERROR(INDEX(hOda,MATCH(16,hSira,0)),"") | B25: =IF($K25="","",INDEX(kAd,$K25)) | C25: =IF($K25="","",INDEX(kKisi,$K25)) | D25: =IF($K25="","",INDEX(kGiris,$K25)) | E25: =IF($K25="","",INDEX(kCikis,$K25)) | F25: =IF($K25="","",INDEX(kSure,$K25)) | G25: =IF($K25="","",INDEX(kGunluk,$K25)) | H25: =IF($K25="","",INDEX(kTutar,$K25)) | I25: =IF($K25="","",INDEX(kKaynak,$K25)&IF(INDEX(kDurum,$K25)="Bekleniyor"," (GELECEK)","")) | K25: =IF(A25="","",MATCH(A25,kAnahtar,0))
A26: =IFERROR(INDEX(hOda,MATCH(17,hSira,0)),"") | B26: =IF($K26="","",INDEX(kAd,$K26)) | C26: =IF($K26="","",INDEX(kKisi,$K26)) | D26: =IF($K26="","",INDEX(kGiris,$K26)) | E26: =IF($K26="","",INDEX(kCikis,$K26)) | F26: =IF($K26="","",INDEX(kSure,$K26)) | G26: =IF($K26="","",INDEX(kGunluk,$K26)) | H26: =IF($K26="","",INDEX(kTutar,$K26)) | I26: =IF($K26="","",INDEX(kKaynak,$K26)&IF(INDEX(kDurum,$K26)="Bekleniyor"," (GELECEK)","")) | K26: =IF(A26="","",MATCH(A26,kAnahtar,0))
A27: =IFERROR(INDEX(hOda,MATCH(18,hSira,0)),"") | B27: =IF($K27="","",INDEX(kAd,$K27)) | C27: =IF($K27="","",INDEX(kKisi,$K27)) | D27: =IF($K27="","",INDEX(kGiris,$K27)) | E27: =IF($K27="","",INDEX(kCikis,$K27)) | F27: =IF($K27="","",INDEX(kSure,$K27)) | G27: =IF($K27="","",INDEX(kGunluk,$K27)) | H27: =IF($K27="","",INDEX(kTutar,$K27)) | I27: =IF($K27="","",INDEX(kKaynak,$K27)&IF(INDEX(kDurum,$K27)="Bekleniyor"," (GELECEK)","")) | K27: =IF(A27="","",MATCH(A27,kAnahtar,0))
A28: =IFERROR(INDEX(hOda,MATCH(19,hSira,0)),"") | B28: =IF($K28="","",INDEX(kAd,$K28)) | C28: =IF($K28="","",INDEX(kKisi,$K28)) | D28: =IF($K28="","",INDEX(kGiris,$K28)) | E28: =IF($K28="","",INDEX(kCikis,$K28)) | F28: =IF($K28="","",INDEX(kSure,$K28)) | G28: =IF($K28="","",INDEX(kGunluk,$K28)) | H28: =IF($K28="","",INDEX(kTutar,$K28)) | I28: =IF($K28="","",INDEX(kKaynak,$K28)&IF(INDEX(kDurum,$K28)="Bekleniyor"," (GELECEK)","")) | K28: =IF(A28="","",MATCH(A28,kAnahtar,0))
A29: =IFERROR(INDEX(hOda,MATCH(20,hSira,0)),"") | B29: =IF($K29="","",INDEX(kAd,$K29)) | C29: =IF($K29="","",INDEX(kKisi,$K29)) | D29: =IF($K29="","",INDEX(kGiris,$K29)) | E29: =IF($K29="","",INDEX(kCikis,$K29)) | F29: =IF($K29="","",INDEX(kSure,$K29)) | G29: =IF($K29="","",INDEX(kGunluk,$K29)) | H29: =IF($K29="","",INDEX(kTutar,$K29)) | I29: =IF($K29="","",INDEX(kKaynak,$K29)&IF(INDEX(kDurum,$K29)="Bekleniyor"," (GELECEK)","")) | K29: =IF(A29="","",MATCH(A29,kAnahtar,0))
A30: =IFERROR(INDEX(hOda,MATCH(21,hSira,0)),"") | B30: =IF($K30="","",INDEX(kAd,$K30)) | C30: =IF($K30="","",INDEX(kKisi,$K30)) | D30: =IF($K30="","",INDEX(kGiris,$K30)) | E30: =IF($K30="","",INDEX(kCikis,$K30)) | F30: =IF($K30="","",INDEX(kSure,$K30)) | G30: =IF($K30="","",INDEX(kGunluk,$K30)) | H30: =IF($K30="","",INDEX(kTutar,$K30)) | I30: =IF($K30="","",INDEX(kKaynak,$K30)&IF(INDEX(kDurum,$K30)="Bekleniyor"," (GELECEK)","")) | K30: =IF(A30="","",MATCH(A30,kAnahtar,0))
A31: =IFERROR(INDEX(hOda,MATCH(22,hSira,0)),"") | B31: =IF($K31="","",INDEX(kAd,$K31)) | C31: =IF($K31="","",INDEX(kKisi,$K31)) | D31: =IF($K31="","",INDEX(kGiris,$K31)) | E31: =IF($K31="","",INDEX(kCikis,$K31)) | F31: =IF($K31="","",INDEX(kSure,$K31)) | G31: =IF($K31="","",INDEX(kGunluk,$K31)) | H31: =IF($K31="","",INDEX(kTutar,$K31)) | I31: =IF($K31="","",INDEX(kKaynak,$K31)&IF(INDEX(kDurum,$K31)="Bekleniyor"," (GELECEK)","")) | K31: =IF(A31="","",MATCH(A31,kAnahtar,0))
A32: =IFERROR(INDEX(hOda,MATCH(23,hSira,0)),"") | B32: =IF($K32="","",INDEX(kAd,$K32)) | C32: =IF($K32="","",INDEX(kKisi,$K32)) | D32: =IF($K32="","",INDEX(kGiris,$K32)) | E32: =IF($K32="","",INDEX(kCikis,$K32)) | F32: =IF($K32="","",INDEX(kSure,$K32)) | G32: =IF($K32="","",INDEX(kGunluk,$K32)) | H32: =IF($K32="","",INDEX(kTutar,$K32)) | I32: =IF($K32="","",INDEX(kKaynak,$K32)&IF(INDEX(kDurum,$K32)="Bekleniyor"," (GELECEK)","")) | K32: =IF(A32="","",MATCH(A32,kAnahtar,0))
A33: =IFERROR(INDEX(hOda,MATCH(24,hSira,0)),"") | B33: =IF($K33="","",INDEX(kAd,$K33)) | C33: =IF($K33="","",INDEX(kKisi,$K33)) | D33: =IF($K33="","",INDEX(kGiris,$K33)) | E33: =IF($K33="","",INDEX(kCikis,$K33)) | F33: =IF($K33="","",INDEX(kSure,$K33)) | G33: =IF($K33="","",INDEX(kGunluk,$K33)) | H33: =IF($K33="","",INDEX(kTutar,$K33)) | I33: =IF($K33="","",INDEX(kKaynak,$K33)&IF(INDEX(kDurum,$K33)="Bekleniyor"," (GELECEK)","")) | K33: =IF(A33="","",MATCH(A33,kAnahtar,0))
A34: =IFERROR(INDEX(hOda,MATCH(25,hSira,0)),"") | B34: =IF($K34="","",INDEX(kAd,$K34)) | C34: =IF($K34="","",INDEX(kKisi,$K34)) | D34: =IF($K34="","",INDEX(kGiris,$K34)) | E34: =IF($K34="","",INDEX(kCikis,$K34)) | F34: =IF($K34="","",INDEX(kSure,$K34)) | G34: =IF($K34="","",INDEX(kGunluk,$K34)) | H34: =IF($K34="","",INDEX(kTutar,$K34)) | I34: =IF($K34="","",INDEX(kKaynak,$K34)&IF(INDEX(kDurum,$K34)="Bekleniyor"," (GELECEK)","")) | K34: =IF(A34="","",MATCH(A34,kAnahtar,0))
A35: =IFERROR(INDEX(hOda,MATCH(26,hSira,0)),"") | B35: =IF($K35="","",INDEX(kAd,$K35)) | C35: =IF($K35="","",INDEX(kKisi,$K35)) | D35: =IF($K35="","",INDEX(kGiris,$K35)) | E35: =IF($K35="","",INDEX(kCikis,$K35)) | F35: =IF($K35="","",INDEX(kSure,$K35)) | G35: =IF($K35="","",INDEX(kGunluk,$K35)) | H35: =IF($K35="","",INDEX(kTutar,$K35)) | I35: =IF($K35="","",INDEX(kKaynak,$K35)&IF(INDEX(kDurum,$K35)="Bekleniyor"," (GELECEK)","")) | K35: =IF(A35="","",MATCH(A35,kAnahtar,0))
A36: =IFERROR(INDEX(hOda,MATCH(27,hSira,0)),"") | B36: =IF($K36="","",INDEX(kAd,$K36)) | C36: =IF($K36="","",INDEX(kKisi,$K36)) | D36: =IF($K36="","",INDEX(kGiris,$K36)) | E36: =IF($K36="","",INDEX(kCikis,$K36)) | F36: =IF($K36="","",INDEX(kSure,$K36)) | G36: =IF($K36="","",INDEX(kGunluk,$K36)) | H36: =IF($K36="","",INDEX(kTutar,$K36)) | I36: =IF($K36="","",INDEX(kKaynak,$K36)&IF(INDEX(kDurum,$K36)="Bekleniyor"," (GELECEK)","")) | K36: =IF(A36="","",MATCH(A36,kAnahtar,0))
A37: =IFERROR(INDEX(hOda,MATCH(28,hSira,0)),"") | B37: =IF($K37="","",INDEX(kAd,$K37)) | C37: =IF($K37="","",INDEX(kKisi,$K37)) | D37: =IF($K37="","",INDEX(kGiris,$K37)) | E37: =IF($K37="","",INDEX(kCikis,$K37)) | F37: =IF($K37="","",INDEX(kSure,$K37)) | G37: =IF($K37="","",INDEX(kGunluk,$K37)) | H37: =IF($K37="","",INDEX(kTutar,$K37)) | I37: =IF($K37="","",INDEX(kKaynak,$K37)&IF(INDEX(kDurum,$K37)="Bekleniyor"," (GELECEK)","")) | K37: =IF(A37="","",MATCH(A37,kAnahtar,0))
A38: =IFERROR(INDEX(hOda,MATCH(29,hSira,0)),"") | B38: =IF($K38="","",INDEX(kAd,$K38)) | C38: =IF($K38="","",INDEX(kKisi,$K38)) | D38: =IF($K38="","",INDEX(kGiris,$K38)) | E38: =IF($K38="","",INDEX(kCikis,$K38)) | F38: =IF($K38="","",INDEX(kSure,$K38)) | G38: =IF($K38="","",INDEX(kGunluk,$K38)) | H38: =IF($K38="","",INDEX(kTutar,$K38)) | I38: =IF($K38="","",INDEX(kKaynak,$K38)&IF(INDEX(kDurum,$K38)="Bekleniyor"," (GELECEK)","")) | K38: =IF(A38="","",MATCH(A38,kAnahtar,0))
A39: =IFERROR(INDEX(hOda,MATCH(30,hSira,0)),"") | B39: =IF($K39="","",INDEX(kAd,$K39)) | C39: =IF($K39="","",INDEX(kKisi,$K39)) | D39: =IF($K39="","",INDEX(kGiris,$K39)) | E39: =IF($K39="","",INDEX(kCikis,$K39)) | F39: =IF($K39="","",INDEX(kSure,$K39)) | G39: =IF($K39="","",INDEX(kGunluk,$K39)) | H39: =IF($K39="","",INDEX(kTutar,$K39)) | I39: =IF($K39="","",INDEX(kKaynak,$K39)&IF(INDEX(kDurum,$K39)="Bekleniyor"," (GELECEK)","")) | K39: =IF(A39="","",MATCH(A39,kAnahtar,0))
A41: Toplam Oda | C41: Toplam Kişi | G41: Günlük Toplam | H41: Günlük Ort
A42: =COUNT(A10:A39) | C42: =SUM(C10:C39) | G42: =SUM(G10:G39) | H42: =IFERROR(G42/A42,0)
A44: ÖDEME - ODA | B44: ÖDEMEYİ YAPAN | C44: TUTAR | D44: ÖDEME TÜRÜ | E44: AÇIKLAMA
...

Sheet Konaklama
A1: KONAKLAMA KAYITLARI
A2: Her konaklama için BİR satır girin (odadan çıkan misafir de silinmez, kayıtta kalır). Sarı hücreler girilir, gri hücreler otomatiktir. Kontrol sütunu 'OK' olmadan rapor onaylanmaz.
A3: Giriş Durumu: Bekleniyor = bugün gelecek ama henüz gelmedi · Geldi = otele giriş yaptı · İptal = gelmedi/iptal.
A5: Oda No | B5: Misafir Adı | C5: Kişi Sayısı | D5: Giriş Tarihi | E5: Çıkış Tarihi | F5: Giriş Durumu | G5: Toplam Tutar | H5: Açıklama / Kaynak | I5: Süre (Gün) | J5: Günlük Oda Fiyatı | K5: Kontrol | L5: Gün Sonu Anahtar
A6: 18 | B6: MUHAMMET SEMİH KÖSE | C6: 4 | D6: 46278 | E6: 46563 | F6: Geldi | G6: 498192 | H6: ÖĞRENCİ | I6: =IF(AND(ISNUMBER(D6),ISNUMBER(E6)),E6-D6,"") | J6: =IF(AND(ISNUMBER(I6),ISNUMBER(G6)),IF(I6>0,G6/I6,""),"") | K6: =IF(COUNTA(A6:H6)=0,"",IF(OR(A6="",B6="",C6="",D6="",E6="",F6="",G6="",H6=""),"HATA: eksik bilgi",IF(COUNTIF(OdaListesi,A6)=0,"HATA: geçersiz oda no",IF(OR(NOT(ISNUMBER(D6)),NOT(ISNUMBER(E6))),"HATA: tarih geçersiz",IF(E6<=D6,"HATA: çıkış girişten sonra olmalı",IF(OR(NOT(ISNUMBER(C6)),C6<1,C6>MaxKisi,C6<>INT(C6)),"HATA: kişi sayısı geçersiz",IF(OR(NOT(ISNUMBER(G6)),G6<0),"HATA: tutar geçersiz",IF(B6<>TRIM(B6),"HATA: isimde baştaki/sondaki boşluk",IF(COUNTIF(KaynakAralik,H6)=0,"HATA: kaynak listede yok",IF(AND(F6<>"Bekleniyor",F6<>"Geldi",F6<>"İptal"),"HATA: giriş durumu geçersiz",IF(AND(F6<>"İptal",COUNTIFS($A$6:$A$1005,A6,$D$6:$D$1005,"<"&E6,$E$6:$E$1005,">"&D6,$F$6:$F$1005,"<>İptal")>1),"HATA: oda bu tarihlerde çakışıyor",IF(AND(F6="Bekleniyor",D6<RaporTarihi),"HATA: giriş günü geçti, Geldi veya İptal yapın","OK")))))))))))) | L6: =IF(AND(ISNUMBER(A6),F6<>"İptal",ISNUMBER(D6),ISNUMBER(E6),D6<=RaporTarihi,E6>RaporTarihi),A6,"")
A7: 20 | B7: MEHMET EFE ÇELEBİ | C7: 4 | D7: 46286 | E7: 46553 | F7: Geldi | G7: 471522 | H7: ÖĞRENCİ | I7: =IF(AND(ISNUMBER(D7),ISNUMBER(E7)),E7-D7,"") | J7: =IF(AND(ISNUMBER(I7),ISNUMBER(G7)),IF(I7>0,G7/I7,""),"") | K7: =IF(COUNTA(A7:H7)=0,"",IF(OR(A7="",B7="",C7="",D7="",E7="",F7="",G7="",H7=""),"HATA: eksik bilgi",IF(COUNTIF(OdaListesi,A7)=0,"HATA: geçersiz oda no",IF(OR(NOT(ISNUMBER(D7)),NOT(ISNUMBER(E7))),"HATA: tarih geçersiz",IF(E7<=D7,"HATA: çıkış girişten sonra olmalı",IF(OR(NOT(ISNUMBER(C7)),C7<1,C7>MaxKisi,C7<>INT(C7)),"HATA: kişi sayısı geçersiz",IF(OR(NOT(ISNUMBER(G7)),G7<0),"HATA: tutar geçersiz",IF(B7<>TRIM(B7),"HATA: isimde baştaki/sondaki boşluk",IF(COUNTIF(KaynakAralik,H7)=0,"HATA: kaynak listede yok",IF(AND(F7<>"Bekleniyor",F7<>"Geldi",F7<>"İptal"),"HATA: giriş durumu geçersiz",IF(AND(F7<>"İptal",COUNTIFS($A$6:$A$1005,A7,$D$6:$D$1005,"<"&E7,$E$6:$E$1005,">"&D7,$F$6:$F$1005,"<>İptal")>1),"HATA: oda bu tarihlerde çakışıyor",IF(AND(F7="Bekleniyor",D7<RaporTarihi),"HATA: giriş günü geçti, Geldi veya İptal yapın","OK")))))))))))) | L7: =IF(AND(ISNUMBER(A7),F7<>"İptal",ISNUMBER(D7),ISNUMBER(E7),D7<=RaporTarihi,E7>RaporTarihi),A7,"")
A8: 22 | B8: HAYAL YAVAŞ | C8: 4 | D8: 46281 | E8: 46553 | F8: Geldi | G8: 480352 | H8: ÖĞRENCİ | I8: =IF(AND(ISNUMBER(D8),ISNUMBER(E8)),E8-D8,"") | J8: =IF(AND(ISNUMBER(I8),ISNUMBER(G8)),IF(I8>0,G8/I8,""),"") | K8: =IF(COUNTA(A8:H8)=0,"",IF(OR(A8="",B8="",C8="",D8="",E8="",F8="",G8="",H8=""),"HATA: eksik bilgi",IF(COUNTIF(OdaListesi,A8)=0,"HATA: geçersiz oda no",IF(OR(NOT(ISNUMBER(D8)),NOT(ISNUMBER(E8))),"HATA: tarih geçersiz",IF(E8<=D8,"HATA: çıkış girişten sonra olmalı",IF(OR(NOT(ISNUMBER(C8)),C8<1,C8>MaxKisi,C8<>INT(C8)),"HATA: kişi sayısı geçersiz",IF(OR(NOT(ISNUMBER(G8)),G8<0),"HATA: tutar geçersiz",IF(B8<>TRIM(B8),"HATA: isimde baştaki/sondaki boşluk",IF(COUNTIF(KaynakAralik,H8)=0,"HATA: kaynak listede yok",IF(AND(F8<>"Bekleniyor",F8<>"Geldi",F8<>"İptal"),"HATA: giriş durumu geçersiz",IF(AND(F8<>"İptal",COUNTIFS($A$6:$A$1005,A8,$D$6:$D$1005,"<"&E8,$E$6:$E$1005,">"&D8,$F$6:$F$1005,"<>İptal")>1),"HATA: oda bu tarihlerde çakışıyor",IF(AND(F8="Bekleniyor",D8<RaporTarihi),"HATA: giriş günü geçti, Geldi veya İptal yapın","OK")))))))))))) | L8: =IF(AND(ISNUMBER(A8),F8<>"İptal",ISNUMBER(D8),ISNUMBER(E8),D8<=RaporTarihi,E8>RaporTarihi),A8,"")
A9: 24 | B9: BEREN TEZSEZENER | C9: 2 | D9: 46277 | E9: 46553 | F9: Geldi | G9: 482298 | H9: ÖĞRENCİ | I9: =IF(AND(ISNUMBER(D9),ISNUMBER(E9)),E9-D9,"") | J9: =IF(AND(ISNUMBER(I9),ISNUMBER(G9)),IF(I9>0,G9/I9,""),"") | K9: =IF(COUNTA(A9:H9)=0,"",IF(OR(A9="",B9="",C9="",D9="",E9="",F9="",G9="",H9=""),"HATA: eksik bilgi",IF(COUNTIF(OdaListesi,A9)=0,"HATA: geçersiz oda no",IF(OR(NOT(ISNUMBER(D9)),NOT(ISNUMBER(E9))),"HATA: tarih geçersiz",IF(E9<=D9,"HATA: çıkış girişten sonra olmalı",IF(OR(NOT(ISNUMBER(C9)),C9<1,C9>MaxKisi,C9<>INT(C9)),"HATA: kişi sayısı geçersiz",IF(OR(NOT(ISNUMBER(G9)),G9<0),"HATA: tutar geçersiz",IF(B9<>TRIM(B9),"HATA: isimde baştaki/sondaki boşluk",IF(COUNTIF(KaynakAralik,H9)=0,"HATA: kaynak listede yok",IF(AND(F9<>"Bekleniyor",F9<>"Geldi",F9<>"İptal"),"HATA: giriş durumu geçersiz",IF(AND(F9<>"İptal",COUNTIFS($A$6:$A$1005,A9,$D$6:$D$1005,"<"&E9,$E$6:$E$1005,">"&D9,$F$6:$F$1005,"<>İptal")>1),"HATA: oda bu tarihlerde çakışıyor",IF(AND(F9="Bekleniyor",D9<RaporTarihi),"HATA: giriş günü geçti, Geldi veya İptal yapın","OK")))))))))))) | L9: =IF(AND(ISNUMBER(A9),F9<>"İptal",ISNUMBER(D9),ISNUMBER(E9),D9<=RaporTarihi,E9>RaporTarihi),A9,"")
A10: 26 | B10: HİLAL KIVRAK | C10: 2 | D10: 46269 | E10: 46553 | F10: Geldi | G10: 496450 | H10: ÖĞRENCİ | I10: =IF(AND(ISNUMBER(D10),ISNUMBER(E10)),E10-D10,"") | J10: =IF(AND(ISNUMBER(I10),ISNUMBER(G10)),IF(I10>0,G10/I10,""),"") | K10: =IF(COUNTA(A10:H10)=0,"",IF(OR(A10="",B10="",C10="",D10="",E10="",F10="",G10="",H10=""),"HATA: eksik bilgi",IF(COUNTIF(OdaListesi,A10)=0,"HATA: geçersiz oda no",IF(OR(NOT(ISNUMBER(D10)),NOT(ISNUMBER(E10))),"HATA: tarih geçersiz",IF(E10<=D10,"HATA: çıkış girişten sonra olmalı",IF(OR(NOT(ISNUMBER(C10)),C10<1,C10>MaxKisi,C10<>INT(C10)),"HATA: kişi sayısı geçersiz",IF(OR(NOT(ISNUMBER(G10)),G10<0),"HATA: tutar geçersiz",IF(B10<>TRIM(B10),"HATA: isimde baştaki/sondaki boşluk",IF(COUNTIF(KaynakAralik,H10)=0,"HATA: kaynak listede yok",IF(AND(F10<>"Bekleniyor",F10<>"Geldi",F10<>"İptal"),"HATA: giriş durumu geçersiz",IF(AND(F10<>"İptal",COUNTIFS($A$6:$A$1005,A10,$D$6:$D$1005,"<"&E10,$E$6:$E$1005,">"&D10,$F$6:$F$1005,"<>İptal")>1),"HATA: oda bu tarihlerde çakışıyor",IF(AND(F10="Bekleniyor",D10<RaporTarihi),"HATA: giriş günü geçti, Geldi veya İptal yapın","OK")))))))))))) | L10: =IF(AND(ISNUMBER(A10),F10<>"İptal",ISNUMBER(D10),ISNUMBER(E10),D10<=RaporTarihi,E10>RaporTarihi),A10,"")
A11: 29 | B11: EDA NUR RUŞİTLER | C11: 2 | D11: 46278 | E11: 46553 | F11: Geldi | G11: 480532 | H11: ÖĞRENCİ | I11: =IF(AND(ISNUMBER(D11),ISNUMBER(E11)),E11-D11,"") | J11: =IF(AND(ISNUMBER(I11),ISNUMBER(G11)),IF(I11>0,G11/I11,""),"") | K11: =IF(COUNTA(A11:H11)=0,"",IF(OR(A11="",B11="",C11="",D11="",E11="",F11="",G11="",H11=""),"HATA: eksik bilgi",IF(COUNTIF(OdaListesi,A11)=0,"HATA: geçersiz oda no",IF(OR(NOT(ISNUMBER(D11)),NOT(ISNUMBER(E11))),"HATA: tarih geçersiz",IF(E11<=D11,"HATA: çıkış girişten sonra olmalı",IF(OR(NOT(ISNUMBER(C11)),C11<1,C11>MaxKisi,C11<>INT(C11)),"HATA: kişi sayısı geçersiz",IF(OR(NOT(ISNUMBER(G11)),G11<0),"HATA: tutar geçersiz",IF(B11<>TRIM(B11),"HATA: isimde baştaki/sondaki boşluk",IF(COUNTIF(KaynakAralik,H11)=0,"HATA: kaynak listede yok",IF(AND(F11<>"Bekleniyor",F11<>"Geldi",F11<>"İptal"),"HATA: giriş durumu geçersiz",IF(AND(F11<>"İptal",COUNTIFS($A$6:$A$1005,A11,$D$6:$D$1005,"<"&E11,$E$6:$E$1005,">"&D11,$F$6:$F$1005,"<>İptal")>1),"HATA: oda bu tarihlerde çakışıyor",IF(AND(F11="Bekleniyor",D11<RaporTarihi),"HATA: giriş günü geçti, Geldi veya İptal yapın","OK")))))))))))) | L11: =IF(AND(ISNUMBER(A11),F11<>"İptal",ISNUMBER(D11),ISNUMBER(E11),D11<=RaporTarihi,E11>RaporTarihi),A11,"")
A12: 13 | B12: ZAKARIA EL KHATABI | C12: 3 | D12: 46290 | E12: 46296 | F12: Geldi | G12: 30600 | H12: MÜNFERİT | I12: =IF(AND(ISNUMBER(D12),ISNUMBER(E12)),E12-D12,"") | J12: =IF(AND(ISNUMBER(I12),ISNUMBER(G12)),IF(I12>0,G12/I12,""),"") | K12: =IF(COUNTA(A12:H12)=0,"",IF(OR(A12="",B12="",C12="",D12="",E12="",F12="",G12="",H12=""),"HATA: eksik bilgi",IF(COUNTIF(OdaListesi,A12)=0,"HATA: geçersiz oda no",IF(OR(NOT(ISNUMBER(D12)),NOT(ISNUMBER(E12))),"HATA: tarih geçersiz",IF(E12<=D12,"HATA: çıkış girişten sonra olmalı",IF(OR(NOT(ISNUMBER(C12)),C12<1,C12>MaxKisi,C12<>INT(C12)),"HATA: kişi sayısı geçersiz",IF(OR(NOT(ISNUMBER(G12)),G12<0),"HATA: tutar geçersiz",IF(B12<>TRIM(B12),"HATA: isimde baştaki/sondaki boşluk",IF(COUNTIF(KaynakAralik,H12)=0,"HATA: kaynak listede yok",IF(AND(F12<>"Bekleniyor",F12<>"Geldi",F12<>"İptal"),"HATA: giriş durumu geçersiz",IF(AND(F12<>"İptal",COUNTIFS($A$6:$A$1005,A12,$D$6:$D$1005,"<"&E12,$E$6:$E$1005,">"&D12,$F$6:$F$1005,"<>İptal")>1),"HATA: oda bu tarihlerde çakışıyor",IF(AND(F12="Bekleniyor",D12<RaporTarihi),"HATA: giriş günü geçti, Geldi veya İptal yapın","OK")))))))))))) | L12: =IF(AND(ISNUMBER(A12),F12<>"İptal",ISNUMBER(D12),ISNUMBER(E12),D12<=RaporTarihi,E12>RaporTarihi),A12,"")
A13: 16 | B13: SALİH ARABAYAPAN | C13: 5 | D13: 46292 | E13: 46299 | F13: Geldi | G13: 37999.99 | H13: MÜNFERİT | I13: =IF(AND(ISNUMBER(D13),ISNUMBER(E13)),E13-D13,"") | J13: =IF(AND(ISNUMBER(I13),ISNUMBER(G13)),IF(I13>0,G13/I13,""),"") | K13: =IF(COUNTA(A13:H13)=0,"",IF(OR(A13="",B13="",C13="",D13="",E13="",F13="",G13="",H13=""),"HATA: eksik bilgi",IF(COUNTIF(OdaListesi,A13)=0,"HATA: geçersiz oda no",IF(OR(NOT(ISNUMBER(D13)),NOT(ISNUMBER(E13))),"HATA: tarih geçersiz",IF(E13<=D13,"HATA: çıkış girişten sonra olmalı",IF(OR(NOT(ISNUMBER(C13)),C13<1,C13>MaxKisi,C13<>INT(C13)),"HATA: kişi sayısı geçersiz",IF(OR(NOT(ISNUMBER(G13)),G13<0),"HATA: tutar geçersiz",IF(B13<>TRIM(B13),"HATA: isimde baştaki/sondaki boşluk",IF(COUNTIF(KaynakAralik,H13)=0,"HATA: kaynak listede yok",IF(AND(F13<>"Bekleniyor",F13<>"Geldi",F13<>"İptal"),"HATA: giriş durumu geçersiz",IF(AND(F13<>"İptal",COUNTIFS($A$6:$A$1005,A13,$D$6:$D$1005,"<"&E13,$E$6:$E$1005,">"&D13,$F$6:$F$1005,"<>İptal")>1),"HATA: oda bu tarihlerde çakışıyor",IF(AND(F13="Bekleniyor",D13<RaporTarihi),"HATA: giriş günü geçti, Geldi veya İptal yapın","OK")))))))))))) | L13: =IF(AND(ISNUMBER(A13),F13<>"İptal",ISNUMBER(D13),ISNUMBER(E13),D13<=RaporTarihi,E13>RaporTarihi),A13,"")
A14: 31 | B14: MEHMET EMIN DINC | C14: 4 | D14: 46291 | E14: 46298 | F14: Geldi | G14: 37087 | H14: ODAMAX | I14: =IF(AND(ISNUMBER(D14),ISNUMBER(E14)),E14-D14,"") | J14: =IF(AND(ISNUMBER(I14),ISNUMBER(G14)),IF(I14>0,G14/I14,""),"") | K14: =IF(COUNTA(A14:H14)=0,"",IF(OR(A14="",B14="",C14="",D14="",E14="",F14="",G14="",H14=""),"HATA: eksik bilgi",IF(COUNTIF(OdaListesi,A14)=0,"HATA: geçersiz oda no",IF(OR(NOT(ISNUMBER(D14)),NOT(ISNUMBER(E14))),"HATA: tarih geçersiz",IF(E14<=D14,"HATA: çıkış girişten sonra olmalı",IF(OR(NOT(ISNUMBER(C14)),C14<1,C14>MaxKisi,C14<>INT(C14)),"HATA: kişi sayısı geçersiz",IF(OR(NOT(ISNUMBER(G14)),G14<0),"HATA: tutar geçersiz",IF(B14<>TRIM(B14),"HATA: isimde baştaki/sondaki boşluk",IF(COUNTIF(KaynakAralik,H14)=0,"HATA: kaynak listede yok",IF(AND(F14<>"Bekleniyor",F14<>"Geldi",F14<>"İptal"),"HATA: giriş durumu geçersiz",IF(AND(F14<>"İptal",COUNTIFS($A$6:$A$1005,A14,$D$6:$D$1005,"<"&E14,$E$6:$E$1005,">"&D14,$F$6:$F$1005,"<>İptal")>1),"HATA: oda bu tarihlerde çakışıyor",IF(AND(F14="Bekleniyor",D14<RaporTarihi),"HATA: giriş günü geçti, Geldi veya İptal yapın","OK")))))))))))) | L14: =IF(AND(ISNUMBER(A14),F14<>"İptal",ISNUMBER(D14),ISNUMBER(E14),D14<=RaporTarihi,E14>RaporTarihi),A14,"")
A15: 8 | B15: KÜBRA TOPRAK KOLCU | C15: 4 | D15: 46295 | E15: 46296 | F15: Geldi | G15: 4337 | H15: JOLLYTUR | I15: =IF(AND(ISNUMBER(D15),ISNUMBER(E15)),E15-D15,"") | J15: =IF(AND(ISNUMBER(I15),ISNUMBER(G15)),IF(I15>0,G15/I15,""),"") | K15: =IF(COUNTA(A15:H15)=0,"",IF(OR(A15="",B15="",C15="",D15="",E15="",F15="",G15="",H15=""),"HATA: eksik bilgi",IF(COUNTIF(OdaListesi,A15)=0,"HATA: geçersiz oda no",IF(OR(NOT(ISNUMBER(D15)),NOT(ISNUMBER(E15))),"HATA: tarih geçersiz",IF(E15<=D15,"HATA: çıkış girişten sonra olmalı",IF(OR(NOT(ISNUMBER(C15)),C15<1,C15>MaxKisi,C15<>INT(C15)),"HATA: kişi sayısı geçersiz",IF(OR(NOT(ISNUMBER(G15)),G15<0),"HATA: tutar geçersiz",IF(B15<>TRIM(B15),"HATA: isimde baştaki/sondaki boşluk",IF(COUNTIF(KaynakAralik,H15)=0,"HATA: kaynak listede yok",IF(AND(F15<>"Bekleniyor",F15<>"Geldi",F15<>"İptal"),"HATA: giriş durumu geçersiz",IF(AND(F15<>"İptal",COUNTIFS($A$6:$A$1005,A15,$D$6:$D$1005,"<"&E15,$E$6:$E$1005,">"&D15,$F$6:$F$1005,"<>İptal")>1),"HATA: oda bu tarihlerde çakışıyor",IF(AND(F15="Bekleniyor",D15<RaporTarihi),"HATA: giriş günü geçti, Geldi veya İptal yapın","OK")))))))))))) | L15: =IF(AND(ISNUMBER(A15),F15<>"İptal",ISNUMBER(D15),ISNUMBER(E15),D15<=RaporTarihi,E15>RaporTarihi),A15,"")
A16: 14 | B16: BATI BAKKALOĞLU | C16: 5 | D16: 46295 | E16: 46299 | F16: Geldi | G16: 20000 | H16: MÜNFERİT | I16: =IF(AND(ISNUMBER(D16),ISNUMBER(E16)),E16-D16,"") | J16: =IF(AND(ISNUMBER(I16),ISNUMBER(G16)),IF(I16>0,G16/I16,""),"") | K16: =IF(COUNTA(A16:H16)=0,"",IF(OR(A16="",B16="",C16="",D16="",E16="",F16="",G16="",H16=""),"HATA: eksik bilgi",IF(COUNTIF(OdaListesi,A16)=0,"HATA: geçersiz oda no",IF(OR(NOT(ISNUMBER(D16)),NOT(ISNUMBER(E16))),"HATA: tarih geçersiz",IF(E16<=D16,"HATA: çıkış girişten sonra olmalı",IF(OR(NOT(ISNUMBER(C16)),C16<1,C16>MaxKisi,C16<>INT(C16)),"HATA: kişi sayısı geçersiz",IF(OR(NOT(ISNUMBER(G16)),G16<0),"HATA: tutar geçersiz",IF(B16<>TRIM(B16),"HATA: isimde baştaki/sondaki boşluk",IF(COUNTIF(KaynakAralik,H16)=0,"HATA: kaynak listede yok",IF(AND(F16<>"Bekleniyor",F16<>"Geldi",F16<>"İptal"),"HATA: giriş durumu geçersiz",IF(AND(F16<>"İptal",COUNTIFS($A$6:$A$1005,A16,$D$6:$D$1005,"<"&E16,$E$6:$E$1005,">"&D16,$F$6:$F$1005,"<>İptal")>1),"HATA: oda bu tarihlerde çakışıyor",IF(AND(F16="Bekleniyor",D16<RaporTarihi),"HATA: giriş günü geçti, Geldi veya İptal yapın","OK")))))))))))) | L16: =IF(AND(ISNUMBER(A16),F16<>"İptal",ISNUMBER(D16),ISNUMBER(E16),D16<=RaporTarihi,E16>RaporTarihi),A16,"")
A17: 25 | B17: MEHMET YENER | C17: 4 | D17: 46295 | E17: 46299 | F17: Bekleniyor | G17: 2000 | H17: COMP-MARATON | I17: =IF(AND(ISNUMBER(D17),ISNUMBER(E17)),E17-D17,"") | J17: =IF(AND(ISNUMBER(I17),ISNUMBER(G17)),IF(I17>0,G17/I17,""),"") | K17: =IF(COUNTA(A17:H17)=0,"",IF(OR(A17="",B17="",C17="",D17="",E17="",F17="",G17="",H17=""),"HATA: eksik bilgi",IF(COUNTIF(OdaListesi,A17)=0,"HATA: geçersiz oda no",IF(OR(NOT(ISNUMBER(D17)),NOT(ISNUMBER(E17))),"HATA: tarih geçersiz",IF(E17<=D17,"HATA: çıkış girişten sonra olmalı",IF(OR(NOT(ISNUMBER(C17)),C17<1,C17>MaxKisi,C17<>INT(C17)),"HATA: kişi sayısı geçersiz",IF(OR(NOT(ISNUMBER(G17)),G17<0),"HATA: tutar geçersiz",IF(B17<>TRIM(B17),"HATA: isimde baştaki/sondaki boşluk",IF(COUNTIF(KaynakAralik,H17)=0,"HATA: kaynak listede yok",IF(AND(F17<>"Bekleniyor",F17<>"Geldi",F17<>"İptal"),"HATA: giriş durumu geçersiz",IF(AND(F17<>"İptal",COUNTIFS($A$6:$A$1005,A17,$D$6:$D$1005,"<"&E17,$E$6:$E$1005,">"&D17,$F$6:$F$1005,"<>İptal")>1),"HATA: oda bu tarihlerde çakışıyor",IF(AND(F17="Bekleniyor",D17<RaporTarihi),"HATA: giriş günü geçti, Geldi veya İptal yapın","OK")))))))))))) | L17: =IF(AND(ISNUMBER(A17),F17<>"İptal",ISNUMBER(D17),ISNUMBER(E17),D17<=RaporTarihi,E17>RaporTarihi),A17,"")
... A21: 8 | B21: ÖRNEK GİDEN MİSAFİR 08 | C21: 4 | D21: 46292 | E21: 46295 | F21: Geldi | G21: 0 | H21: MÜNFERİT | I21: =IF(AND(ISNUMBER(D21),ISNUMBER(E21)),E21-D21,"") | J21: =IF(AND(ISNUMBER(I21),ISNUMBER(G21)),IF(I21>0,G21/I21,""),"") | K21: =IF(COUNTA(A21:H21)=0,"",IF(OR(A21="",B21="",C21="",D21="",E21="",F21="",G21="",H21=""),"HATA: eksik bilgi",IF(COUNTIF(OdaListesi,A21)=0,"HATA: geçersiz oda no",IF(OR(NOT(ISNUMBER(D21)),NOT(ISNUMBER(E21))),"HATA: tarih geçersiz",IF(E21<=D21,"HATA: çıkış girişten sonra olmalı",IF(OR(NOT(ISNUMBER(C21)),C21<1,C21>MaxKisi,C21<>INT(C21)),"HATA: kişi sayısı geçersiz",IF(OR(NOT(ISNUMBER(G21)),G21<0),"HATA: tutar geçersiz",IF(B21<>TRIM(B21),"HATA: isimde baştaki/sondaki boşluk",IF(COUNTIF(KaynakAralik,H21)=0,"HATA: kaynak listede yok",IF(AND(F21<>"Bekleniyor",F21<>"Geldi",F21<>"İptal"),"HATA: giriş durumu geçersiz",IF(AND(F21<>"İptal",COUNTIFS($A$6:$A$1005,A21,$D$6:$D$1005,"<"&E21,$E$6:$E$1005,">"&D21,$F$6:$F$1005,"<>İptal")>1),"HATA: oda bu tarihlerde çakışıyor",IF(AND(F21="Bekleniyor",D21<RaporTarihi),"HATA: giriş günü geçti, Geldi veya İptal yapın","OK")))))))))))) | L21: =IF(AND(ISNUMBER(A21),F21<>"İptal",ISNUMBER(D21),ISNUMBER(E21),D21<=RaporTarihi,E21>RaporTarihi),A21,"")
I22: =IF(AND(ISNUMBER(D22),ISNUMBER(E22)),E22-D22,"") | J22: =IF(AND(ISNUMBER(I22),ISNUMBER(G22)),IF(I22>0,G22/I22,""),"") | K22: =IF(COUNTA(A22:H22)=0,"",IF(OR(A22="",B22="",C22="",D22="",E22="",F22="",G22="",H22=""),"HATA: eksik bilgi",IF(COUNTIF(OdaListesi,A22)=0,"HATA: geçersiz oda no",IF(OR(NOT(ISNUMBER(D22)),NOT(ISNUMBER(E22))),"HATA: tarih geçersiz",IF(E22<=D22,"HATA: çıkış girişten sonra olmalı",IF(OR(NOT(ISNUMBER(C22)),C22<1,C22>MaxKisi,C22<>INT(C22)),"HATA: kişi sayısı geçersiz",IF(OR(NOT(ISNUMBER(G22)),G22<0),"HATA: tutar geçersiz",IF(B22<>TRIM(B22),"HATA: isimde baştaki/sondaki boşluk",IF(COUNTIF(KaynakAralik,H22)=0,"HATA: kaynak listede yok",IF(AND(F22<>"Bekleniyor",F22<>"Geldi",F22<>"İptal"),"HATA: giriş durumu geçersiz",IF(AND(F22<>"İptal",COUNTIFS($A$6:$A$1005,A22,$D$6:$D$1005,"<"&E22,$E$6:$E$1005,">"&D22,$F$6:$F$1005,"<>İptal")>1),"HATA: oda bu tarihlerde çakışıyor",IF(AND(F22="Bekleniyor",D22<RaporTarihi),"HATA: giriş günü geçti, Geldi veya İptal yapın","OK")))))))))))) | L22: =IF(AND(ISNUMBER(A22),F22<>"İptal",ISNUMBER(D22),ISNUMBER(E22),D22<=RaporTarihi,E22>RaporTarihi),A22,"")
I23: =IF(AND(ISNUMBER(D23),ISNUMBER(E23)),E23-D23,"") | J23: =IF(AND(ISNUMBER(I23),ISNUMBER(G23)),IF(I23>0,G23/I23,""),"") | K23: =IF(COUNTA(A23:H23)=0,"",IF(OR(A23="",B23="",C23="",D23="",E23="",F23="",G23="",H23=""),"HATA: eksik bilgi",IF(COUNTIF(OdaListesi,A23)=0,"HATA: geçersiz oda no",IF(OR(NOT(ISNUMBER(D23)),NOT(ISNUMBER(E23))),"HATA: tarih geçersiz",IF(E23<=D23,"HATA: çıkış girişten sonra olmalı",IF(OR(NOT(ISNUMBER(C23)),C23<1,C23>MaxKisi,C23<>INT(C23)),"HATA: kişi sayısı geçersiz",IF(OR(NOT(ISNUMBER(G23)),G23<0),"HATA: tutar geçersiz",IF(B23<>TRIM(B23),"HATA: isimde baştaki/sondaki boşluk",IF(COUNTIF(KaynakAralik,H23)=0,"HATA: kaynak listede yok",IF(AND(F23<>"Bekleniyor",F23<>"Geldi",F23<>"İptal"),"HATA: giriş durumu geçersiz",IF(AND(F23<>"İptal",COUNTIFS($A$6:$A$1005,A23,$D$6:$D$1005,"<"&E23,$E$6:$E$1005,">"&D23,$F$6:$F$1005,"<>İptal")>1),"HATA: oda bu tarihlerde çakışıyor",IF(AND(F23="Bekleniyor",D23<RaporTarihi),"HATA: giriş günü geçti, Geldi veya İptal yapın","OK")))))))))))) | L23: =IF(AND(ISNUMBER(A23),F23<>"İptal",ISNUMBER(D23),ISNUMBER(E23),D23<=RaporTarihi,E23>RaporTarihi),A23,"")
I24: =IF(AND(ISNUMBER(D24),ISNUMBER(E24)),E24-D24,"") | J24: =IF(AND(ISNUMBER(I24),ISNUMBER(G24)),IF(I24>0,G24/I24,""),"") | K24: =IF(COUNTA(A24:H24)=0,"",IF(OR(A24="",B24="",C24="",D24="",E24="",F24="",G24="",H24=""),"HATA: eksik bilgi",IF(COUNTIF(OdaListesi,A24)=0,"HATA: geçersiz oda no",IF(OR(NOT(ISNUMBER(D24)),NOT(ISNUMBER(E24))),"HATA: tarih geçersiz",IF(E24<=D24,"HATA: çıkış girişten sonra olmalı",IF(OR(NOT(ISNUMBER(C24)),C24<1,C24>MaxKisi,C24<>INT(C24)),"HATA: kişi sayısı geçersiz",IF(OR(NOT(ISNUMBER(G24)),G24<0),"HATA: tutar geçersiz",IF(B24<>TRIM(B24),"HATA: isimde baştaki/sondaki boşluk",IF(COUNTIF(KaynakAralik,H24)=0,"HATA: kaynak listede yok",IF(AND(F24<>"Bekleniyor",F24<>"Geldi",F24<>"İptal"),"HATA: giriş durumu geçersiz",IF(AND(F24<>"İptal",COUNTIFS($A$6:$A$1005,A24,$D$6:$D$1005,"<"&E24,$E$6:$E$1005,">"&D24,$F$6:$F$1005,"<>İptal")>1),"HATA: oda bu tarihlerde çakışıyor",IF(AND(F24="Bekleniyor",D24<RaporTarihi),"HATA: giriş günü geçti, Geldi veya İptal yapın","OK")))))))))))) | L24: =IF(AND(ISNUMBER(A24),F24<>"İptal",ISNUMBER(D24),ISNUMBER(E24),D24<=RaporTarihi,E24>RaporTarihi),A24,"")
I25: =IF(AND(ISNUMBER(D25),ISNUMBER(E25)),E25-D25,"") | J25: =IF(AND(ISNUMBER(I25),ISNUMBER(G25)),IF(I25>0,G25/I25,""),"") | K25: =IF(COUNTA(A25:H25)=0,"",IF(OR(A25="",B25="",C25="",D25="",E25="",F25="",G25="",H25=""),"HATA: eksik bilgi",IF(COUNTIF(OdaListesi,A25)=0,"HATA: geçersiz oda no",IF(OR(NOT(ISNUMBER(D25)),NOT(ISNUMBER(E25))),"HATA: tarih geçersiz",IF(E25<=D25,"HATA: çıkış girişten sonra olmalı",IF(OR(NOT(ISNUMBER(C25)),C25<1,C25>MaxKisi,C25<>INT(C25)),"HATA: kişi sayısı geçersiz",IF(OR(NOT(ISNUMBER(G25)),G25<0),"HATA: tutar geçersiz",IF(B25<>TRIM(B25),"HATA: isimde baştaki/sondaki boşluk",IF(COUNTIF(KaynakAralik,H25)=0,"HATA: kaynak listede yok",IF(AND(F25<>"Bekleniyor",F25<>"Geldi",F25<>"İptal"),"HATA: giriş durumu geçersiz",IF(AND(F25<>"İptal",COUNTIFS($A$6:$A$1005,A25,$D$6:$D$1005,"<"&E25,$E$6:$E$1005,">"&D25,$F$6:$F$1005,"<>İptal")>1),"HATA: oda bu tarihlerde çakışıyor",IF(AND(F25="Bekleniyor",D25<RaporTarihi),"HATA: giriş günü geçti, Geldi veya İptal yapın","OK")))))))))))) | L25: =IF(AND(ISNUMBER(A25),F25<>"İptal",ISNUMBER(D25),ISNUMBER(E25),D25<=RaporTarihi,E25>RaporTarihi),A25,"")
I26: =IF(AND(ISNUMBER(D26),ISNUMBER(E26)),E26-D26,"") | J26: =IF(AND(ISNUMBER(I26),ISNUMBER(G26)),IF(I26>0,G26/I26,""),"") | K26: =IF(COUNTA(A26:H26)=0,"",IF(OR(A26="",B26="",C26="",D26="",E26="",F26="",G26="",H26=""),"HATA: eksik bilgi",IF(COUNTIF(OdaListesi,A26)=0,"HATA: geçersiz oda no",IF(OR(NOT(ISNUMBER(D26)),NOT(ISNUMBER(E26))),"HATA: tarih geçersiz",IF(E26<=D26,"HATA: çıkış girişten sonra olmalı",IF(OR(NOT(ISNUMBER(C26)),C26<1,C26>MaxKisi,C26<>INT(C26)),"HATA: kişi sayısı geçersiz",IF(OR(NOT(ISNUMBER(G26)),G26<0),"HATA: tutar geçersiz",IF(B26<>TRIM(B26),"HATA: isimde baştaki/sondaki boşluk",IF(COUNTIF(KaynakAralik,H26)=0,"HATA: kaynak listede yok",IF(AND(F26<>"Bekleniyor",F26<>"Geldi",F26<>"İptal"),"HATA: giriş durumu geçersiz",IF(AND(F26<>"İptal",COUNTIFS($A$6:$A$1005,A26,$D$6:$D$1005,"<"&E26,$E$6:$E$1005,">"&D26,$F$6:$F$1005,"<>İptal")>1),"HATA: oda bu tarihlerde çakışıyor",IF(AND(F26="Bekleniyor",D26<RaporTarihi),"HATA: giriş günü geçti, Geldi veya İptal yapın","OK")))))))))))) | L26: =IF(AND(ISNUMBER(A26),F26<>"İptal",ISNUMBER(D26),ISNUMBER(E26),D26<=RaporTarihi,E26>RaporTarihi),A26,"")
I27: =IF(AND(ISNUMBER(D27),ISNUMBER(E27)),E27-D27,"") | J27: =IF(AND(ISNUMBER(I27),ISNUMBER(G27)),IF(I27>0,G27/I27,""),"") | K27: =IF(COUNTA(A27:H27)=0,"",IF(OR(A27="",B27="",C27="",D27="",E27="",F27="",G27="",H27=""),"HATA: eksik bilgi",IF(COUNTIF(OdaListesi,A27)=0,"HATA: geçersiz oda no",IF(OR(NOT(ISNUMBER(D27)),NOT(ISNUMBER(E27))),"HATA: tarih geçersiz",IF(E27<=D27,"HATA: çıkış girişten sonra olmalı",IF(OR(NOT(ISNUMBER(C27)),C27<1,C27>MaxKisi,C27<>INT(C27)),"HATA: kişi sayısı geçersiz",IF(OR(NOT(ISNUMBER(G27)),G27<0),"HATA: tutar geçersiz",IF(B27<>TRIM(B27),"HATA: isimde baştaki/sondaki boşluk",IF(COUNTIF(KaynakAralik,H27)=0,"HATA: kaynak listede yok",IF(AND(F27<>"Bekleniyor",F27<>"Geldi",F27<>"İptal"),"HATA: giriş durumu geçersiz",IF(AND(F27<>"İptal",COUNTIFS($A$6:$A$1005,A27,$D$6:$D$1005,"<"&E27,$E$6:$E$1005,">"&D27,$F$6:$F$1005,"<>İptal")>1),"HATA: oda bu tarihlerde çakışıyor",IF(AND(F27="Bekleniyor",D27<RaporTarihi),"HATA: giriş günü geçti, Geldi veya İptal yapın","OK")))))))))))) | L27: =IF(AND(ISNUMBER(A27),F27<>"İptal",ISNUMBER(D27),ISNUMBER(E27),D27<=RaporTarihi,E27>RaporTarihi),A27,"")
I28: =IF(AND(ISNUMBER(D28),ISNUMBER(E28)),E28-D28,"") | J28: =IF(AND(ISNUMBER(I28),ISNUMBER(G28)),IF(I28>0,G28/I28,""),"") | K28: =IF(COUNTA(A28:H28)=0,"",IF(OR(A28="",B28="",C28="",D28="",E28="",F28="",G28="",H28=""),"HATA: eksik bilgi",IF(COUNTIF(OdaListesi,A28)=0,"HATA: geçersiz oda no",IF(OR(NOT(ISNUMBER(D28)),NOT(ISNUMBER(E28))),"HATA: tarih geçersiz",IF(E28<=D28,"HATA: çıkış girişten sonra olmalı",IF(OR(NOT(ISNUMBER(C28)),C28<1,C28>MaxKisi,C28<>INT(C28)),"HATA: kişi sayısı geçersiz",IF(OR(NOT(ISNUMBER(G28)),G28<0),"HATA: tutar geçersiz",IF(B28<>TRIM(B28),"HATA: isimde baştaki/sondaki boşluk",IF(COUNTIF(KaynakAralik,H28)=0,"HATA: kaynak listede yok",IF(AND(F28<>"Bekleniyor",F28<>"Geldi",F28<>"İptal"),"HATA: giriş durumu geçersiz",IF(AND(F28<>"İptal",COUNTIFS($A$6:$A$1005,A28,$D$6:$D$1005,"<"&E28,$E$6:$E$1005,">"&D28,$F$6:$F$1005,"<>İptal")>1),"HATA: oda bu tarihlerde çakışıyor",IF(AND(F28="Bekleniyor",D28<RaporTarihi),"HATA: giriş günü geçti, Geldi veya İptal yapın","OK")))))))))))) | L28: =IF(AND(ISNUMBER(A28),F28<>"İptal",ISNUMBER(D28),ISNUMBER(E28),D28<=RaporTarihi,E28>RaporTarihi),A28,"")
I29: =IF(AND(ISNUMBER(D29),ISNUMBER(E29)),E29-D29,"") | J29: =IF(AND(ISNUMBER(I29),ISNUMBER(G29)),IF(I29>0,G29/I29,""),"") | K29: =IF(COUNTA(A29:H29)=0,"",IF(OR(A29="",B29="",C29="",D29="",E29="",F29="",G29="",H29=""),"HATA: eksik bilgi",IF(COUNTIF(OdaListesi,A29)=0,"HATA: geçersiz oda no",IF(OR(NOT(ISNUMBER(D29)),NOT(ISNUMBER(E29))),"HATA: tarih geçersiz",IF(E29<=D29,"HATA: çıkış girişten sonra olmalı",IF(OR(NOT(ISNUMBER(C29)),C29<1,C29>MaxKisi,C29<>INT(C29)),"HATA: kişi sayısı geçersiz",IF(OR(NOT(ISNUMBER(G29)),G29<0),"HATA: tutar geçersiz",IF(B29<>TRIM(B29),"HATA: isimde baştaki/sondaki boşluk",IF(COUNTIF(KaynakAralik,H29)=0,"HATA: kaynak listede yok",IF(AND(F29<>"Bekleniyor",F29<>"Geldi",F29<>"İptal"),"HATA: giriş durumu geçersiz",IF(AND(F29<>"İptal",COUNTIFS($A$6:$A$1005,A29,$D$6:$D$1005,"<"&E29,$E$6:$E$1005,">"&D29,$F$6:$F$1005,"<>İptal")>1),"HATA: oda bu tarihlerde çakışıyor",IF(AND(F29="Bekleniyor",D29<RaporTarihi),"HATA: giriş günü geçti, Geldi veya İptal yapın","OK")))))))))))) | L29: =IF(AND(ISNUMBER(A29),F29<>"İptal",ISNUMBER(D29),ISNUMBER(E29),D29<=RaporTarihi,E29>RaporTarihi),A29,"")
I30: =IF(AND(ISNUMBER(D30),ISNUMBER(E30)),E30-D30,"") | J30: =IF(AND(ISNUMBER(I30),ISNUMBER(G30)),IF(I30>0,G30/I30,""),"") | K30: =IF(COUNTA(A30:H30)=0,"",IF(OR(A30="",B30="",C30="",D30="",E30="",F30="",G30="",H30=""),"HATA: eksik bilgi",IF(COUNTIF(OdaListesi,A30)=0,"HATA: geçersiz oda no",IF(OR(NOT(ISNUMBER(D30)),NOT(ISNUMBER(E30))),"HATA: tarih geçersiz",IF(E30<=D30,"HATA: çıkış girişten sonra olmalı",IF(OR(NOT(ISNUMBER(C30)),C30<1,C30>MaxKisi,C30<>INT(C30)),"HATA: kişi sayısı geçersiz",IF(OR(NOT(ISNUMBER(G30)),G30<0),"HATA: tutar geçersiz",IF(B30<>TRIM(B30),"HATA: isimde baştaki/sondaki boşluk",IF(COUNTIF(KaynakAralik,H30)=0,"HATA: kaynak listede yok",IF(AND(F30<>"Bekleniyor",F30<>"Geldi",F30<>"İptal"),"HATA: giriş durumu geçersiz",IF(AND(F30<>"İptal",COUNTIFS($A$6:$A$1005,A30,$D$6:$D$1005,"<"&E30,$E$6:$E$1005,">"&D30,$F$6:$F$1005,"<>İptal")>1),"HATA: oda bu tarihlerde çakışıyor",IF(AND(F30="Bekleniyor",D30<RaporTarihi),"HATA: giriş günü geçti, Geldi veya İptal yapın","OK")))))))))))) | L30: =IF(AND(ISNUMBER(A30),F30<>"İptal",ISNUMBER(D30),ISNUMBER(E30),D30<=RaporTarihi,E30>RaporTarihi),A30,"")
I31: =IF(AND(ISNUMBER(D31),ISNUMBER(E31)),E31-D31,"") | J31: =IF(AND(ISNUMBER(I31),ISNUMBER(G31)),IF(I31>0,G31/I31,""),"") | K31: =IF(COUNTA(A31:H31)=0,"",IF(OR(A31="",B31="",C31="",D31="",E31="",F31="",G31="",H31=""),"HATA: eksik bilgi",IF(COUNTIF(OdaListesi,A31)=0,"HATA: geçersiz oda no",IF(OR(NOT(ISNUMBER(D31)),NOT(ISNUMBER(E31))),"HATA: tarih geçersiz",IF(E31<=D31,"HATA: çıkış girişten sonra olmalı",IF(OR(NOT(ISNUMBER(C31)),C31<1,C31>MaxKisi,C31<>INT(C31)),"HATA: kişi sayısı geçersiz",IF(OR(NOT(ISNUMBER(G31)),G31<0),"HATA: tutar geçersiz",IF(B31<>TRIM(B31),"HATA: isimde baştaki/sondaki boşluk",IF(COUNTIF(KaynakAralik,H31)=0,"HATA: kaynak listede yok",IF(AND(F31<>"Bekleniyor",F31<>"Geldi",F31<>"İptal"),"HATA: giriş durumu geçersiz",IF(AND(F31<>"İptal",COUNTIFS($A$6:$A$1005,A31,$D$6:$D$1005,"<"&E31,$E$6:$E$1005,">"&D31,$F$6:$F$1005,"<>İptal")>1),"HATA: oda bu tarihlerde çakışıyor",IF(AND(F31="Bekleniyor",D31<RaporTarihi),"HATA: giriş günü geçti, Geldi veya İptal yapın","OK")))))))))))) | L31: =IF(AND(ISNUMBER(A31),F31<>"İptal",ISNUMBER(D31),ISNUMBER(E31),D31<=RaporTarihi,E31>RaporTarihi),A31,"")
I32: =IF(AND(ISNUMBER(D32),ISNUMBER(E32)),E32-D32,"") | J32: =IF(AND(ISNUMBER(I32),ISNUMBER(G32)),IF(I32>0,G32/I32,""),"") | K32: =IF(COUNTA(A32:H32)=0,"",IF(OR(A32="",B32="",C32="",D32="",E32="",F32="",G32="",H32=""),"HATA: eksik bilgi",IF(COUNTIF(OdaListesi,A32)=0,"HATA: geçersiz oda no",IF(OR(NOT(ISNUMBER(D32)),NOT(ISNUMBER(E32))),"HATA: tarih geçersiz",IF(E32<=D32,"HATA: çıkış girişten sonra olmalı",IF(OR(NOT(ISNUMBER(C32)),C32<1,C32>MaxKisi,C32<>INT(C32)),"HATA: kişi sayısı geçersiz",IF(OR(NOT(ISNUMBER(G32)),G32<0),"HATA: tutar geçersiz",IF(B32<>TRIM(B32),"HATA: isimde baştaki/sondaki boşluk",IF(COUNTIF(KaynakAralik,H32)=0,"HATA: kaynak listede yok",IF(AND(F32<>"Bekleniyor",F32<>"Geldi",F32<>"İptal"),"HATA: giriş durumu geçersiz",IF(AND(F32<>"İptal",COUNTIFS($A$6:$A$1005,A32,$D$6:$D$1005,"<"&E32,$E$6:$E$1005,">"&D32,$F$6:$F$1005,"<>İptal")>1),"HATA: oda bu tarihlerde çakışıyor",IF(AND(F32="Bekleniyor",D32<RaporTarihi),"HATA: giriş günü geçti, Geldi veya İptal yapın","OK")))))))))))) | L32: =IF(AND(ISNUMBER(A32),F32<>"İptal",ISNUMBER(D32),ISNUMBER(E32),D32<=RaporTarihi,E32>RaporTarihi),A32,"")
I33: =IF(AND(ISNUMBER(D33),ISNUMBER(E33)),E33-D33,"") | J33: =IF(AND(ISNUMBER(I33),ISNUMBER(G33)),IF(I33>0,G33/I33,""),"") | K33: =IF(COUNTA(A33:H33)=0,"",IF(OR(A33="",B33="",C33="",D33="",E33="",F33="",G33="",H33=""),"HATA: eksik bilgi",IF(COUNTIF(OdaListesi,A33)=0,"HATA: geçersiz oda no",IF(OR(NOT(ISNUMBER(D33)),NOT(ISNUMBER(E33))),"HATA: tarih geçersiz",IF(E33<=D33,"HATA: çıkış girişten sonra olmalı",IF(OR(NOT(ISNUMBER(C33)),C33<1,C33>MaxKisi,C33<>INT(C33)),"HATA: kişi sayısı geçersiz",IF(OR(NOT(ISNUMBER(G33)),G33<0),"HATA: tutar geçersiz",IF(B33<>TRIM(B33),"HATA: isimde baştaki/sondaki boşluk",IF(COUNTIF(KaynakAralik,H33)=0,"HATA: kaynak listede yok",IF(AND(F33<>"Bekleniyor",F33<>"Geldi",F33<>"İptal"),"HATA: giriş durumu geçersiz",IF(AND(F33<>"İptal",COUNTIFS($A$6:$A$1005,A33,$D$6:$D$1005,"<"&E33,$E$6:$E$1005,">"&D33,$F$6:$F$1005,"<>İptal")>1),"HATA: oda bu tarihlerde çakışıyor",IF(AND(F33="Bekleniyor",D33<RaporTarihi),"HATA: giriş günü geçti, Geldi veya İptal yapın","OK")))))))))))) | L33: =IF(AND(ISNUMBER(A33),F33<>"İptal",ISNUMBER(D33),ISNUMBER(E33),D33<=RaporTarihi,E33>RaporTarihi),A33,"")
... I1005: =IF(AND(ISNUMBER(D1005),ISNUMBER(E1005)),E1005-D1005,"") | J1005: =IF(AND(ISNUMBER(I1005),ISNUMBER(G1005)),IF(I1005>0,G1005/I1005,""),"") | K1005: =IF(COUNTA(A1005:H1005)=0,"",IF(OR(A1005="",B1005="",C1005="",D1005="",E1005="",F1005="",G1005="",H1005=""),"HATA: eksik bilgi",IF(COUNTIF(OdaListesi,A1005)=0,"HATA: geçersiz oda no",IF(OR(NOT(ISNUMBER(D1005)),NOT(ISNUMBER(E1005))),"HATA: tarih geçersiz",IF(E1005<=D1005,"HATA: çıkış girişten sonra olmalı",IF(OR(NOT(ISNUMBER(C1005)),C1005<1,C1005>MaxKisi,C1005<>INT(C1005)),"HATA: kişi sayısı geçersiz",IF(OR(NOT(ISNUMBER(G1005)),G1005<0),"HATA: tutar geçersiz",IF(B1005<>TRIM(B1005),"HATA: isimde baştaki/sondaki boşluk",IF(COUNTIF(KaynakAralik,H1005)=0,"HATA: kaynak listede yok",IF(AND(F1005<>"Bekleniyor",F1005<>"Geldi",F1005<>"İptal"),"HATA: giriş durumu geçersiz",IF(AND(F1005<>"İptal",COUNTIFS($A$6:$A$1005,A1005,$D$6:$D$1005,"<"&E1005,$E$6:$E$1005,">"&D1005,$F$6:$F$1005,"<>İptal")>1),"HATA: oda bu tarihlerde çakışıyor",IF(AND(F1005="Bekleniyor",D1005<RaporTarihi),"HATA: giriş günü geçti, Geldi veya İptal yapın","OK")))))))))))) | L1005: =IF(AND(ISNUMBER(A1005),F1005<>"İptal",ISNUMBER(D1005),ISNUMBER(E1005),D1005<=RaporTarihi,E1005>RaporTarihi),A1005,"")

Sheet Ödemeler
A1: ÖDEME KAYITLARI
A2: Alınan her ödeme için bir satır. Tarih = ödemenin alındığı gün. Odada o tarihte misafir yoksa sistem kabul etmez.
A5: Tarih | B5: Oda No | C5: Ödemeyi Yapan | D5: Tutar | E5: Ödeme Türü | F5: Açıklama (isteğe bağlı) | G5: Kontrol | H5: Sıra
A6: 46295 | B6: 14 | C6: BATI BAKKALOĞLU | D6: 10000 | E6: KK | G6: =IF(COUNTA(A6:F6)=0,"",IF(OR(A6="",B6="",C6="",D6="",E6=""),"HATA: eksik bilgi",IF(OR(NOT(ISNUMBER(A6)),NOT(ISNUMBER(D6)),D6<=0),"HATA: tarih/tutar geçersiz",IF(C6<>TRIM(C6),"HATA: isimde baştaki/sondaki boşluk",IF(COUNTIF(TurAralik,E6)=0,"HATA: ödeme türü geçersiz",IF(COUNTIFS(kOda,B6,kGiris,"<="&A6,kCikis,">="&A6,kDurum,"<>İptal")=0,"HATA: bu odada o tarihte misafir yok","OK")))))) | H6: =IF(AND(ISNUMBER(A6),A6=RaporTarihi),COUNTIFS($A$6:A6,RaporTarihi),"")
G7: =IF(COUNTA(A7:F7)=0,"",IF(OR(A7="",B7="",C7="",D7="",E7=""),"HATA: eksik bilgi",IF(OR(NOT(ISNUMBER(A7)),NOT(ISNUMBER(D7)),D7<=0),"HATA: tarih/tutar geçersiz",IF(C7<>TRIM(C7),"HATA: isimde baştaki/sondaki boşluk",IF(COUNTIF(TurAralik,E7)=0,"HATA: ödeme türü geçersiz",IF(COUNTIFS(kOda,B7,kGiris,"<="&A7,kCikis,">="&A7,kDurum,"<>İptal")=0,"HATA: bu odada o tarihte misafir yok","OK")))))) | H7: =IF(AND(ISNUMBER(A7),A7=RaporTarihi),COUNTIFS($A$6:A7,RaporTarihi),"")
G8: =IF(COUNTA(A8:F8)=0,"",IF(OR(A8="",B8="",C8="",D8="",E8=""),"HATA: eksik bilgi",IF(OR(NOT(ISNUMBER(A8)),NOT(ISNUMBER(D8)),D8<=0),"HATA: tarih/tutar geçersiz",IF(C8<>TRIM(C8),"HATA: isimde baştaki/sondaki boşluk",IF(COUNTIF(TurAralik,E8)=0,"HATA: ödeme türü geçersiz",IF(COUNTIFS(kOda,B8,kGiris,"<="&A8,kCikis,">="&A8,kDurum,"<>İptal")=0,"HATA: bu odada o tarihte misafir yok","OK")))))) | H8: =IF(AND(ISNUMBER(A8),A8=RaporTarihi),COUNTIFS($A$6:A8,RaporTarihi),"")
G9: =IF(COUNTA(A9:F9)=0,"",IF(OR(A9="",B9="",C9="",D9="",E9=""),"HATA: eksik bilgi",IF(OR(NOT(ISNUMBER(A9)),NOT(ISNUMBER(D9)),D9<=0),"HATA: tarih/tutar geçersiz",IF(C9<>TRIM(C9),"HATA: isimde baştaki/sondaki boşluk",IF(COUNTIF(TurAralik,E9)=0,"HATA: ödeme türü geçersiz",IF(COUNTIFS(kOda,B9,kGiris,"<="&A9,kCikis,">="&A9,kDurum,"<>İptal")=0,"HATA: bu odada o tarihte misafir yok","OK")))))) | H9: =IF(AND(ISNUMBER(A9),A9=RaporTarihi),COUNTIFS($A$6:A9,RaporTarihi),"")
G10: =IF(COUNTA(A10:F10)=0,"",IF(OR(A10="",B10="",C10="",D10="",E10=""),"HATA: eksik bilgi",IF(OR(NOT(ISNUMBER(A10)),NOT(ISNUMBER(D10)),D10<=0),"HATA: tarih/tutar geçersiz",IF(C10<>TRIM(C10),"HATA: isimde baştaki/sondaki boşluk",IF(COUNTIF(TurAralik,E10)=0,"HATA: ödeme türü geçersiz",IF(COUNTIFS(kOda,B10,kGiris,"<="&A10,kCikis,">="&A10,kDurum,"<>İptal")=0,"HATA: bu odada o tarihte misafir yok","OK")))))) | H10: =IF(AND(ISNUMBER(A10),A10=RaporTarihi),COUNTIFS($A$6:A10,RaporTarihi),"")
G11: =IF(COUNTA(A11:F11)=0,"",IF(OR(A11="",B11="",C11="",D11="",E11=""),"HATA: eksik bilgi",IF(OR(NOT(ISNUMBER(A11)),NOT(ISNUMBER(D11)),D11<=0),"HATA: tarih/tutar geçersiz",IF(C11<>TRIM(C11),"HATA: isimde baştaki/sondaki boşluk",IF(COUNTIF(TurAralik,E11)=0,"HATA: ödeme türü geçersiz",IF(COUNTIFS(kOda,B11,kGiris,"<="&A11,kCikis,">="&A11,kDurum,"<>İptal")=0,"HATA: bu odada o tarihte misafir yok","OK")))))) | H11: =IF(AND(ISNUMBER(A11),A11=RaporTarihi),COUNTIFS($A$6:A11,RaporTarihi),"")
G12: =IF(COUNTA(A12:F12)=0,"",IF(OR(A12="",B12="",C12="",D12="",E12=""),"HATA: eksik bilgi",IF(OR(NOT(ISNUMBER(A12)),NOT(ISNUMBER(D12)),D12<=0),"HATA: tarih/tutar geçersiz",IF(C12<>TRIM(C12),"HATA: isimde baştaki/sondaki boşluk",IF(COUNTIF(TurAralik,E12)=0,"HATA: ödeme türü geçersiz",IF(COUNTIFS(kOda,B12,kGiris,"<="&A12,kCikis,">="&A12,kDurum,"<>İptal")=0,"HATA: bu odada o tarihte misafir yok","OK")))))) | H12: =IF(AND(ISNUMBER(A12),A12=RaporTarihi),COUNTIFS($A$6:A12,RaporTarihi),"")
G13: =IF(COUNTA(A13:F13)=0,"",IF(OR(A13="",B13="",C13="",D13="",E13=""),"HATA: eksik bilgi",IF(OR(NOT(ISNUMBER(A13)),NOT(ISNUMBER(D13)),D13<=0),"HATA: tarih/tutar geçersiz",IF(C13<>TRIM(C13),"HATA: isimde baştaki/sondaki boşluk",IF(COUNTIF(TurAralik,E13)=0,"HATA: ödeme türü geçersiz",IF(COUNTIFS(kOda,B13,kGiris,"<="&A13,kCikis,">="&A13,kDurum,"<>İptal")=0,"HATA: bu odada o tarihte misafir yok","OK")))))) | H13: =IF(AND(ISNUMBER(A13),A13=RaporTarihi),COUNTIFS($A$6:A13,RaporTarihi),"")
G14: =IF(COUNTA(A14:F14)=0,"",IF(OR(A14="",B14="",C14="",D14="",E14=""),"HATA: eksik bilgi",IF(OR(NOT(ISNUMBER(A14)),NOT(ISNUMBER(D14)),D14<=0),"HATA: tarih/tutar geçersiz",IF(C14<>TRIM(C14),"HATA: isimde baştaki/sondaki boşluk",IF(COUNTIF(TurAralik,E14)=0,"HATA: ödeme türü geçersiz",IF(COUNTIFS(kOda,B14,kGiris,"<="&A14,kCikis,">="&A14,kDurum,"<>İptal")=0,"HATA: bu odada o tarihte misafir yok","OK")))))) | H14: =IF(AND(ISNUMBER(A14),A14=RaporTarihi),COUNTIFS($A$6:A14,RaporTarihi),"")
G15: =IF(COUNTA(A15:F15)=0,"",IF(OR(A15="",B15="",C15="",D15="",E15=""),"HATA: eksik bilgi",IF(OR(NOT(ISNUMBER(A15)),NOT(ISNUMBER(D15)),D15<=0),"HATA: tarih/tutar geçersiz",IF(C15<>TRIM(C15),"HATA: isimde baştaki/sondaki boşluk",IF(COUNTIF(TurAralik,E15)=0,"HATA: ödeme türü geçersiz",IF(COUNTIFS(kOda,B15,kGiris,"<="&A15,kCikis,">="&A15,kDurum,"<>İptal")=0,"HATA: bu odada o tarihte misafir yok","OK")))))) | H15: =IF(AND(ISNUMBER(A15),A15=RaporTarihi),COUNTIFS($A$6:A15,RaporTarihi),"")
G16: =IF(COUNTA(A16:F16)=0,"",IF(OR(A16="",B16="",C16="",D16="",E16=""),"HATA: eksik bilgi",IF(OR(NOT(ISNUMBER(A16)),NOT(ISNUMBER(D16)),D16<=0),"HATA: tarih/tutar geçersiz",IF(C16<>TRIM(C16),"HATA: isimde baştaki/sondaki boşluk",IF(COUNTIF(TurAralik,E16)=0,"HATA: ödeme türü geçersiz",IF(COUNTIFS(kOda,B16,kGiris,"<="&A16,kCikis,">="&A16,kDurum,"<>İptal")=0,"HATA: bu odada o tarihte misafir yok","OK")))))) | H16: =IF(AND(ISNUMBER(A16),A16=RaporTarihi),COUNTIFS($A$6:A16,RaporTarihi),"")
G17: =IF(COUNTA(A17:F17)=0,"",IF(OR(A17="",B17="",C17="",D17="",E17=""),"HATA: eksik bilgi",IF(OR(NOT(ISNUMBER(A17)),NOT(ISNUMBER(D17)),D17<=0),"HATA: tarih/tutar geçersiz",IF(C17<>TRIM(C17),"HATA: isimde baştaki/sondaki boşluk",IF(COUNTIF(TurAralik,E17)=0,"HATA: ödeme türü geçersiz",IF(COUNTIFS(kOda,B17,kGiris,"<="&A17,kCikis,">="&A17,kDurum,"<>İptal")=0,"HATA: bu odada o tarihte misafir yok","OK")))))) | H17: =IF(AND(ISNUMBER(A17),A17=RaporTarihi),COUNTIFS($A$6:A17,RaporTarihi),"")
G18: =IF(COUNTA(A18:F18)=0,"",IF(OR(A18="",B18="",C18="",D18="",E18=""),"HATA: eksik bilgi",IF(OR(NOT(ISNUMBER(A18)),NOT(ISNUMBER(D18)),D18<=0),"HATA: tarih/tutar geçersiz",IF(C18<>TRIM(C18),"HATA: isimde baştaki/sondaki boşluk",IF(COUNTIF(TurAralik,E18)=0,"HATA: ödeme türü geçersiz",IF(COUNTIFS(kOda,B18,kGiris,"<="&A18,kCikis,">="&A18,kDurum,"<>İptal")=0,"HATA: bu odada o tarihte misafir yok","OK")))))) | H18: =IF(AND(ISNUMBER(A18),A18=RaporTarihi),COUNTIFS($A$6:A18,RaporTarihi),"")
... G505: =IF(COUNTA(A505:F505)=0,"",IF(OR(A505="",B505="",C505="",D505="",E505=""),"HATA: eksik bilgi",IF(OR(NOT(ISNUMBER(A505)),NOT(ISNUMBER(D505)),D505<=0),"HATA: tarih/tutar geçersiz",IF(C505<>TRIM(C505),"HATA: isimde baştaki/sondaki boşluk",IF(COUNTIF(TurAralik,E505)=0,"HATA: ödeme türü geçersiz",IF(COUNTIFS(kOda,B505,kGiris,"<="&A505,kCikis,">="&A505,kDurum,"<>İptal")=0,"HATA: bu odada o tarihte misafir yok","OK")))))) | H505: =IF(AND(ISNUMBER(A505),A505=RaporTarihi),COUNTIFS($A$6:A505,RaporTarihi),"")

Sheet Ayarlar
A1: AYARLAR (yalnızca yönetici değiştirir)
A3: Oda No | C3: Açıklama / Kaynak listesi | E3: Ödeme türü listesi | G3: Genel
A4: 3 | C4: ÖĞRENCİ | E4: NAKİT | G4: Odada azami kişi | H4: 6
A5: 4 | C5: MÜNFERİT | E5: KK | G5: Yeni kaynak/ödeme türü eklemek için ilgili listenin altındaki boş hücreye yazın.
A6: 5 | C6: ODAMAX | E6: HAVALE/EFT
A7: 6 | C7: JOLLYTUR
A8: 7 | C8: COMP-MARATON
A9: 8
A10: 9
A11: 10
A12: 11
A13: 12
A14: 13
A15: 14
A16: 15
A17: 16
A18: 17
A19: 18
A20: 19
... A33: 32

Sheet Hesap
A1: Oda | B1: GünBaşı | C1: Gelen | D1: Gelecek | E1: Giden | F1: GünSonu | G1: Boş | H1: tGB | I1: tGel | J1: tGlc | K1: tGid | L1: tGS | M1: tBoş | N1: Sıra
A2: =Ayarlar!A4 | B2: =IF(COUNTIFS(kOda,A2,kGiris,"<"&RaporTarihi,kCikis,">="&RaporTarihi,kDurum,"Geldi")>0,1,0) | C2: =IF(COUNTIFS(kOda,A2,kGiris,RaporTarihi,kDurum,"Geldi")>0,1,0) | D2: =IF(COUNTIFS(kOda,A2,kGiris,RaporTarihi,kDurum,"Bekleniyor")>0,1,0) | E2: =IF(COUNTIFS(kOda,A2,kCikis,RaporTarihi,kDurum,"Geldi")>0,1,0) | F2: =IF(COUNTIFS(kOda,A2,kGiris,"<="&RaporTarihi,kCikis,">"&RaporTarihi,kDurum,"<>İptal")>0,1,0) | G2: =1-F2 | H2: =IF(B2=1,TEXT($A2,"00"),"") | I2: =IF(C2=1,TEXT($A2,"00"),"") | J2: =IF(D2=1,TEXT($A2,"00"),"") | K2: =IF(E2=1,TEXT($A2,"00"),"") | L2: =IF(F2=1,TEXT($A2,"00"),"") | M2: =IF(G2=1,TEXT($A2,"00"),"") | N2: =IF(F2=1,COUNTIF(F$2:F2,1),"")
A3: =Ayarlar!A5 | B3: =IF(COUNTIFS(kOda,A3,kGiris,"<"&RaporTarihi,kCikis,">="&RaporTarihi,kDurum,"Geldi")>0,1,0) | C3: =IF(COUNTIFS(kOda,A3,kGiris,RaporTarihi,kDurum,"Geldi")>0,1,0) | D3: =IF(COUNTIFS(kOda,A3,kGiris,RaporTarihi,kDurum,"Bekleniyor")>0,1,0) | E3: =IF(COUNTIFS(kOda,A3,kCikis,RaporTarihi,kDurum,"Geldi")>0,1,0) | F3: =IF(COUNTIFS(kOda,A3,kGiris,"<="&RaporTarihi,kCikis,">"&RaporTarihi,kDurum,"<>İptal")>0,1,0) | G3: =1-F3 | H3: =IF(B3=1,TEXT($A3,"00"),"") | I3: =IF(C3=1,TEXT($A3,"00"),"") | J3: =IF(D3=1,TEXT($A3,"00"),"") | K3: =IF(E3=1,TEXT($A3,"00"),"") | L3: =IF(F3=1,TEXT($A3,"00"),"") | M3: =IF(G3=1,TEXT($A3,"00"),"") | N3: =IF(F3=1,COUNTIF(F$2:F3,1),"")
A4: =Ayarlar!A6 | B4: =IF(COUNTIFS(kOda,A4,kGiris,"<"&RaporTarihi,kCikis,">="&RaporTarihi,kDurum,"Geldi")>0,1,0) | C4: =IF(COUNTIFS(kOda,A4,kGiris,RaporTarihi,kDurum,"Geldi")>0,1,0) | D4: =IF(COUNTIFS(kOda,A4,kGiris,RaporTarihi,kDurum,"Bekleniyor")>0,1,0) | E4: =IF(COUNTIFS(kOda,A4,kCikis,RaporTarihi,kDurum,"Geldi")>0,1,0) | F4: =IF(COUNTIFS(kOda,A4,kGiris,"<="&RaporTarihi,kCikis,">"&RaporTarihi,kDurum,"<>İptal")>0,1,0) | G4: =1-F4 | H4: =IF(B4=1,TEXT($A4,"00"),"") | I4: =IF(C4=1,TEXT($A4,"00"),"") | J4: =IF(D4=1,TEXT($A4,"00"),"") | K4: =IF(E4=1,TEXT($A4,"00"),"") | L4: =IF(F4=1,TEXT($A4,"00"),"") | M4: =IF(G4=1,TEXT($A4,"00"),"") | N4: =IF(F4=1,COUNTIF(F$2:F4,1),"")
A5: =Ayarlar!A7 | B5: =IF(COUNTIFS(kOda,A5,kGiris,"<"&RaporTarihi,kCikis,">="&RaporTarihi,kDurum,"Geldi")>0,1,0) | C5: =IF(COUNTIFS(kOda,A5,kGiris,RaporTarihi,kDurum,"Geldi")>0,1,0) | D5: =IF(COUNTIFS(kOda,A5,kGiris,RaporTarihi,kDurum,"Bekleniyor")>0,1,0) | E5: =IF(COUNTIFS(kOda,A5,kCikis,RaporTarihi,kDurum,"Geldi")>0,1,0) | F5: =IF(COUNTIFS(kOda,A5,kGiris,"<="&RaporTarihi,kCikis,">"&RaporTarihi,kDurum,"<>İptal")>0,1,0) | G5: =1-F5 | H5: =IF(B5=1,TEXT($A5,"00"),"") | I5: =IF(C5=1,TEXT($A5,"00"),"") | J5: =IF(D5=1,TEXT($A5,"00"),"") | K5: =IF(E5=1,TEXT($A5,"00"),"") | L5: =IF(F5=1,TEXT($A5,"00"),"") | M5: =IF(G5=1,TEXT($A5,"00"),"") | N5: =IF(F5=1,COUNTIF(F$2:F5,1),"")
A6: =Ayarlar!A8 | B6: =IF(COUNTIFS(kOda,A6,kGiris,"<"&RaporTarihi,kCikis,">="&RaporTarihi,kDurum,"Geldi")>0,1,0) | C6: =IF(COUNTIFS(kOda,A6,kGiris,RaporTarihi,kDurum,"Geldi")>0,1,0) | D6: =IF(COUNTIFS(kOda,A6,kGiris,RaporTarihi,kDurum,"Bekleniyor")>0,1,0) | E6: =IF(COUNTIFS(kOda,A6,kCikis,RaporTarihi,kDurum,"Geldi")>0,1,0) | F6: =IF(COUNTIFS(kOda,A6,kGiris,"<="&RaporTarihi,kCikis,">"&RaporTarihi,kDurum,"<>İptal")>0,1,0) | G6: =1-F6 | H6: =IF(B6=1,TEXT($A6,"00"),"") | I6: =IF(C6=1,TEXT($A6,"00"),"") | J6: =IF(D6=1,TEXT($A6,"00"),"") | K6: =IF(E6=1,TEXT($A6,"00"),"") | L6: =IF(F6=1,TEXT($A6,"00"),"") | M6: =IF(G6=1,TEXT($A6,"00"),"") | N6: =IF(F6=1,COUNTIF(F$2:F6,1),"")
